<?xml version="1.0" ?>
<!-- =================================================================================== -->
<!-- |    This document was autogenerated by xacro from robot2_final.xacro             | -->
<!-- |    EDITING THIS FILE BY HAND IS NOT RECOMMENDED                                 | -->
<!-- =================================================================================== -->
<robot name="robot2_2">
  <!-- End of Includes -->
  <!-- Start of robot description -->
  <link name="base_footprint"/>
  <joint name="base_footprint_joint" type="fixed">
    <origin rpy="0 0 0" xyz="0 0 0"/>
    <parent link="base_footprint"/>
    <child link="base_link"/>
  </joint>
  <link name="base_link">
    <inertial>
      <mass value="1024"/>
      <origin rpy="0 0 0" xyz="0 0 0.25"/>
      <inertia ixx="170.667" ixy="0" ixz="0" iyy="170.667" iyz="0" izz="170.667"/>
    </inertial>
    <collision>
      <origin rpy="0 0 0" xyz="0 0 0.25"/>
      <geometry>
        <box size="1 1 0.5"/>
      </geometry>
    </collision>
    <visual>
      <origin rpy="0 0 0" xyz="0 0 0.25"/>
      <geometry>
        <box size="1 1 0.5"/>
      </geometry>
    </visual>
  </link>
  <joint name="J_0" type="revolute">
    <axis xyz="0 0 1"/>
    <limit effort="1000" lower="-3.14" upper="3.14" velocity="0.5"/>
    <origin rpy="0 0 0" xyz="0 0 0.5"/>
    <parent link="base_link"/>
    <child link="link_01"/>
  </joint>
  <transmission name="trans_J_0">
    <type>transmission_interface/SimpleTransmission</type>
    <joint name="J_0">
      <hardwareInterface>hardware_interface/PositionJointInterface</hardwareInterface>
    </joint>
    <actuator name="motor_J_0">
      <mechanicalReduction>1</mechanicalReduction>
      <hardwareInterface>hardware_interface/PositionJointInterface</hardwareInterface>
    </actuator>
  </transmission>
  <link name="link_01">
    <inertial>
      <mass value="157.633"/>
      <origin rpy="0 0 0" xyz="0 0 0.2"/>
      <inertia ixx="13.235" ixy="0" ixz="0" iyy="13.235" iyz="0" izz="9.655"/>
    </inertial>
    <collision>
      <origin rpy="0 0 0" xyz="0 0 0.2"/>
      <geometry>
        <mesh filename="package://ex06/meshes/Link1-v2.stl" scale="0.001 0.001 0.001"/>
      </geometry>
    </collision>
    <visual>
      <origin rpy="0 0 0" xyz="0 0 0.2"/>
      <geometry>
        <mesh filename="package://ex06/meshes/Link1-v2.stl" scale="0.001 0.001 0.001"/>
      </geometry>
      <material name="light_black"/>
    </visual>
  </link>
  <joint name="J_1" type="revolute">
    <axis xyz="0 1 0"/>
    <limit effort="1000" lower="-3.14" upper="3.14" velocity="0.5"/>
    <origin rpy="0 0 0" xyz="0 0 0.4"/>
    <parent link="link_01"/>
    <child link="link_02"/>
  </joint>
  <transmission name="trans_J_1">
    <type>transmission_interface/SimpleTransmission</type>
    <joint name="J_1">
      <hardwareInterface>hardware_interface/PositionJointInterface</hardwareInterface>
    </joint>
    <actuator name="motor_J_1">
      <mechanicalReduction>1</mechanicalReduction>
      <hardwareInterface>hardware_interface/PositionJointInterface</hardwareInterface>
    </actuator>
  </transmission>
  <link name="link_02">
    <inertial>
      <mass value="57.906"/>
      <origin rpy="0 0 0" xyz="0 0 0.4"/>
      <inertia ixx="12.679" ixy="0" ixz="0" iyy="12.679" iyz="0" izz="0.651"/>
    </inertial>
    <collision>
      <origin rpy="0 0 0" xyz="0 0 0.4"/>
      <geometry>
        <box size="1 1 0.5"/>
      </geometry>
    </collision>
    <visual>
      <origin rpy="0 0 0" xyz="0 0 0.4"/>
      <geometry>
        <cylinder length="0.8" radius="0.15"/>
      </geometry>
    </visual>
  </link>
  <joint name="J_2" type="revolute">
    <axis xyz="0 1 0"/>
    <limit effort="1000" lower="-3.14" upper="3.14" velocity="0.5"/>
    <origin rpy="0 0 0" xyz="0 0 0.8"/>
    <parent link="link_02"/>
    <child link="link_03"/>
  </joint>
  <transmission name="trans_J_2">
    <type>transmission_interface/SimpleTransmission</type>
    <joint name="J_2">
      <hardwareInterface>hardware_interface/PositionJointInterface</hardwareInterface>
    </joint>
    <actuator name="motor_J_2">
      <mechanicalReduction>1</mechanicalReduction>
      <hardwareInterface>hardware_interface/PositionJointInterface</hardwareInterface>
    </actuator>
  </transmission>
  <link name="link_03">
    <inertial>
      <mass value="57.906"/>
      <origin rpy="0 0 0" xyz="0 0 0.4"/>
      <inertia ixx="12.679" ixy="0" ixz="0" iyy="12.679" iyz="0" izz="0.651"/>
    </inertial>
    <collision>
      <origin rpy="0 0 0" xyz="0 0 0.4"/>
      <geometry>
        <box size="1 1 0.5"/>
      </geometry>
    </collision>
    <visual>
      <origin rpy="0 0 0" xyz="0 0 0.4"/>
      <geometry>
        <cylinder length="0.8" radius="0.15"/>
      </geometry>
    </visual>
  </link>
  <joint name="J_3" type="revolute">
    <axis xyz="0 1 0"/>
    <limit effort="1000" lower="-3.14" upper="3.14" velocity="0.5"/>
    <origin rpy="0 0 0" xyz="0 0 0.8"/>
    <parent link="link_03"/>
    <child link="link_04"/>
  </joint>
  <transmission name="trans_J_3">
    <type>transmission_interface/SimpleTransmission</type>
    <joint name="J_3">
      <hardwareInterface>hardware_interface/PositionJointInterface</hardwareInterface>
    </joint>
    <actuator name="motor_J_3">
      <mechanicalReduction>1</mechanicalReduction>
      <hardwareInterface>hardware_interface/PositionJointInterface</hardwareInterface>
    </actuator>
  </transmission>
  <link name="link_04">
    <inertial>
      <mass value="57.906"/>
      <origin rpy="0 0 0" xyz="0 0 0.4"/>
      <inertia ixx="12.679" ixy="0" ixz="0" iyy="12.679" iyz="0" izz="0.651"/>
    </inertial>
    <collision>
      <origin rpy="0 0 0" xyz="0 0 0.4"/>
      <geometry>
        <box size="1 1 0.5"/>
      </geometry>
    </collision>
    <visual>
      <origin rpy="0 0 0" xyz="0 0 0.4"/>
      <geometry>
        <cylinder length="0.8" radius="0.15"/>
      </geometry>
    </visual>
  </link>
  <joint name="J_4" type="revolute">
    <axis xyz="0 0 1"/>
    <limit effort="1000" lower="-3.14" upper="3.14" velocity="0.5"/>
    <origin rpy="0 0 0" xyz="0 0 0.8"/>
    <parent link="link_04"/>
    <child link="link_05"/>
  </joint>
  <transmission name="trans_J_4">
    <type>transmission_interface/SimpleTransmission</type>
    <joint name="J_4">
      <hardwareInterface>hardware_interface/PositionJointInterface</hardwareInterface>
    </joint>
    <actuator name="motor_J_4">
      <mechanicalReduction>1</mechanicalReduction>
      <hardwareInterface>hardware_interface/PositionJointInterface</hardwareInterface>
    </actuator>
  </transmission>
  <link name="link_05">
    <inertial>
      <mass value="18.056"/>
      <origin rpy="0 0 0" xyz="0 0 0.125"/>
      <inertia ixx="0.479" ixy="0" ixz="0" iyy="0.479" iyz="0" izz="0.204"/>
    </inertial>
    <collision>
      <origin rpy="0 0 0" xyz="0 0 0.125"/>
      <geometry>
        <box size="1 1 0.5"/>
      </geometry>
    </collision>
    <visual>
      <origin rpy="0 0 0" xyz="0 0 0.125"/>
      <geometry>
        <cylinder length="0.25" radius="0.15"/>
      </geometry>
    </visual>
  </link>
  <gazebo>
    <plugin filename="libgazebo_ros_control.so" name="gazebo_ros_control">
      <robotNamespace>/robot2</robotNamespace>
    </plugin>
  </gazebo>
  <gazebo>
    <plugin filename="libgazebo_ros_joint_state_publisher.so" name="joint_state_publisher">
      <robotNamespace>/robot2</robotNamespace>
      <jointName>J_0, J_1, J_2, J_3, J_4</jointName>
      <updateRate>50</updateRate>
    </plugin>
  </gazebo>
</robot>

